<?xml version="1.0" ?>
<!-- =================================================================================== -->
<!-- |    This document was autogenerated by xacro from model/ettorone.xml.xacro       | -->
<!-- |    EDITING THIS FILE BY HAND IS NOT RECOMMENDED                                 | -->
<!-- =================================================================================== -->
<mujoco model="rover">
  <compiler angle="degree" coordinate="local"/>

  <!-- <asset>
    <mesh name="tank" file="../../../mesh/tank.stl"/>
  </asset> -->

  <option gravity="0 0 -9.81"
          timestep="0.002"
          solver="Newton"
          cone="elliptic"
          integrator="implicitfast"
          impratio="10"/>

  <asset>

    <texture name="grid" type="2d" builtin="checker"
             rgb1="1 0.8 0.8"
             rgb2="0.3 0.3 0.3"
             width="512" height="512"/>

    <material name="grid_mat" texture="grid" texrepeat="30 30"/>
  </asset>


  <worldbody>

    <light diffuse="1 1 1" dir="0 0 -1" pos="0 0 50"/>

    <geom name="floor" type="plane"
          size="50 50 0.1"
          material="grid_mat"/>

    <body name="base" pos="0 0 0.3">
      <joint name="base_free" type="free"/>

      <geom mass="15" rgba="1 0 0 0.7" size="0.1375 0.25 0.1375" type="box" />

      <!-- ================= FRONT LEFT ================= -->
      <body name="fl_module" pos="0.32 0.125 0">
        <geom mass="15" rgba="0.2 0.2 0.7 0.8" size="0.1825 0.125 0.1375" type="box"/>

        <body name="fl_steering_link" pos="0 0.125 0">
          <joint axis="0 0 1"
                 name="fl_steering_joint"
                 type="hinge"
                 damping="0.15"
                 frictionloss="0.05"
                 armature="0.1"/>

          <geom rgba="0 0 0 1" size="0.03 0.1375" type="cylinder"/>

          <body euler="90 0 0" name="fl_offset_link" pos="0 0.075 -0.045">
            <geom mass="2.5" rgba="0 0 0 1" size="0.015 0.075" type="cylinder"/>
          </body>

          <body euler="90 0 0" name="fl_wheel" pos="0 0.15 -0.045">
            <joint axis="0 0 1"
                   name="fl_wheel_joint"
                   type="hinge"
                   damping="0.15"
                   frictionloss="0.15"
                   armature="0.12"/>

            <geom condim="6"
                  friction="0.9 0.001 0.001"
                  mass="1"
                  rgba="0 0 0 1"
                  size="0.12 0.03"
                  type="cylinder"/>
          </body>
        </body>
      </body>

      <!-- ================= BACK LEFT ================= -->
      <body name="bl_module" pos="-0.32 0.125 0">
        <geom mass="15" rgba="0.7 0.7 0.0 0.8" size="0.1825 0.125 0.1375" type="box"/>

        <body name="bl_steering_link" pos="0 0.125 0">
          <joint axis="0 0 1"
                 name="bl_steering_joint"
                 type="hinge"
                 damping="0.15"
                 frictionloss="0.05"
                 armature="0.1"/>

          <geom rgba="0 0 0 1" size="0.03 0.1375" type="cylinder"/>

          <body euler="90 0 0" name="bl_offset_link" pos="0 0.075 -0.045">
            <geom mass="2.5" rgba="0 0 0 1" size="0.015 0.075" type="cylinder"/>
          </body>

          <body euler="90 0 0" name="bl_wheel" pos="0 0.15 -0.045">
            <joint axis="0 0 1"
                   name="bl_wheel_joint"
                   type="hinge"
                   damping="0.15"
                   frictionloss="0.15"
                   armature="0.12"/>

            <geom condim="6"
                  friction="0.9 0.001 0.001"
                  mass="1"
                  rgba="0 0 0 1"
                  size="0.12 0.03"
                  type="cylinder"/>
          </body>
        </body>
      </body>

      <!-- ================= FRONT RIGHT ================= -->
      <body name="fr_module" pos="0.32 -0.125 0">
        <geom mass="15" rgba="0.7 0.4 0.55 0.8" size="0.1825 0.125 0.1375" type="box"/>

        <body name="fr_steering_link" pos="0 -0.125 0">
          <joint axis="0 0 1"
                 name="fr_steering_joint"
                 type="hinge"
                 damping="0.15"
                 frictionloss="0.05"
                 armature="0.1"/>

          <geom rgba="0 0 0 1" size="0.03 0.1375" type="cylinder"/>

          <body euler="90 0 0" name="fr_offset_link" pos="0 -0.075 -0.045">
            <geom mass="2.5" rgba="0 0 0 1" size="0.015 0.075" type="cylinder"/>
          </body>

          <body euler="90 0 0" name="fr_wheel" pos="0 -0.15 -0.045">
            <joint axis="0 0 1"
                   name="fr_wheel_joint"
                   type="hinge"
                   damping="0.15"
                   frictionloss="0.15"
                   armature="0.12"/>

            <geom condim="6"
                  friction="0.9 0.001 0.001"
                  mass="1"
                  rgba="0 0 0 1"
                  size="0.12 0.03"
                  type="cylinder"/>
          </body>
        </body>
      </body>

      <!-- ================= BACK RIGHT ================= -->
      <body name="br_module" pos="-0.32 -0.125 0">
        <geom mass="15" rgba="0 0.8 0 0.8" size="0.1825 0.125 0.1375" type="box"/>

        <body name="br_steering_link" pos="0 -0.125 0">
          <joint axis="0 0 1"
                 name="br_steering_joint"
                 type="hinge"
                 damping="0.15"
                 frictionloss="0.05"
                 armature="0.1"/>

          <geom rgba="0 0 0 1" size="0.03 0.1375" type="cylinder"/>

          <body euler="90 0 0" name="br_offset_link" pos="0 -0.075 -0.045">
            <geom mass="2.5" rgba="0 0 0 1" size="0.015 0.075" type="cylinder"/>
          </body>

          <body euler="90 0 0" name="br_wheel" pos="0 -0.15 -0.045">
            <joint axis="0 0 1"
                   name="br_wheel_joint"
                   type="hinge"
                   damping="0.15"
                   frictionloss="0.15"
                   armature="0.12"/>

            <geom condim="6"
                  friction="0.9 0.001 0.001"
                  mass="1"
                  rgba="0 0 0 1"
                  size="0.12 0.03"
                  type="cylinder"/>
          </body>
        </body>
      </body>

    </body>


    <body name="cone_1" pos="2 0 0">
     <joint type="free"/>
      <inertial pos="0 0 0.21"
                mass="0.3"
                diaginertia="0.0015 0.0015 0.0003"/>
        <geom type="cylinder" size="0.22 0.02" pos="0 0 0.02" rgba="0.1 0.1 0.1 1"/>

        <geom type="cylinder" size="0.18 0.035" pos="0 0 0.07" rgba="1 0.4 0 1"/>
        <geom type="cylinder" size="0.16 0.035" pos="0 0 0.12" rgba="1 1 1 1"/>

        <geom type="cylinder" size="0.14 0.035" pos="0 0 0.17" rgba="1 0.4 0 1"/>
        <geom type="cylinder" size="0.12 0.035" pos="0 0 0.22" rgba="1 1 1 1"/>

        <geom type="cylinder" size="0.10 0.035" pos="0 0 0.27" rgba="1 0.4 0 1"/>
        <geom type="cylinder" size="0.08 0.035" pos="0 0 0.32" rgba="1 1 1 1"/>

        <geom type="cylinder" size="0.06 0.035" pos="0 0 0.37" rgba="1 0.4 0 1"/>
        <geom type="cylinder" size="0.04 0.035" pos="0 0 0.42" rgba="1 1 1 1"/>
    </body>
    <body name="cone_5" pos="10 0 0">
     <joint type="free"/>
      <inertial pos="0 0 0.21"
                mass="0.3"
                diaginertia="0.0015 0.0015 0.0003"/>
      <geom type="cylinder" size="0.22 0.02" pos="0 0 0.02" rgba="0.1 0.1 0.1 1"/>

      <geom type="cylinder" size="0.18 0.035" pos="0 0 0.07" rgba="1 0.4 0 1"/>
      <geom type="cylinder" size="0.16 0.035" pos="0 0 0.12" rgba="1 1 1 1"/>

      <geom type="cylinder" size="0.14 0.035" pos="0 0 0.17" rgba="1 0.4 0 1"/>
      <geom type="cylinder" size="0.12 0.035" pos="0 0 0.22" rgba="1 1 1 1"/>

      <geom type="cylinder" size="0.10 0.035" pos="0 0 0.27" rgba="1 0.4 0 1"/>
      <geom type="cylinder" size="0.08 0.035" pos="0 0 0.32" rgba="1 1 1 1"/>

      <geom type="cylinder" size="0.06 0.035" pos="0 0 0.37" rgba="1 0.4 0 1"/>
      <geom type="cylinder" size="0.04 0.035" pos="0 0 0.42" rgba="1 1 1 1"/>
    </body>
    <body name="cone_2" pos="4 0 0">
     <joint type="free"/>
      <inertial pos="0 0 0.21"
                mass="0.3"
                diaginertia="0.0015 0.0015 0.0003"/>
      <geom type="cylinder" size="0.22 0.02" pos="0 0 0.02" rgba="0.1 0.1 0.1 1"/>

      <geom type="cylinder" size="0.18 0.035" pos="0 0 0.07" rgba="1 0.4 0 1"/>
      <geom type="cylinder" size="0.16 0.035" pos="0 0 0.12" rgba="1 1 1 1"/>

      <geom type="cylinder" size="0.14 0.035" pos="0 0 0.17" rgba="1 0.4 0 1"/>
      <geom type="cylinder" size="0.12 0.035" pos="0 0 0.22" rgba="1 1 1 1"/>

      <geom type="cylinder" size="0.10 0.035" pos="0 0 0.27" rgba="1 0.4 0 1"/>
      <geom type="cylinder" size="0.08 0.035" pos="0 0 0.32" rgba="1 1 1 1"/>

      <geom type="cylinder" size="0.06 0.035" pos="0 0 0.37" rgba="1 0.4 0 1"/>
      <geom type="cylinder" size="0.04 0.035" pos="0 0 0.42" rgba="1 1 1 1"/>
    </body>
    <body name="cone_3" pos="6 0 0">
     <joint type="free"/>
      <inertial pos="0 0 0.21"
                mass="0.3"
                diaginertia="0.0015 0.0015 0.0003"/>
      <geom type="cylinder" size="0.22 0.02" pos="0 0 0.02" rgba="0.1 0.1 0.1 1"/>

      <geom type="cylinder" size="0.18 0.035" pos="0 0 0.07" rgba="1 0.4 0 1"/>
      <geom type="cylinder" size="0.16 0.035" pos="0 0 0.12" rgba="1 1 1 1"/>

      <geom type="cylinder" size="0.14 0.035" pos="0 0 0.17" rgba="1 0.4 0 1"/>
      <geom type="cylinder" size="0.12 0.035" pos="0 0 0.22" rgba="1 1 1 1"/>

      <geom type="cylinder" size="0.10 0.035" pos="0 0 0.27" rgba="1 0.4 0 1"/>
      <geom type="cylinder" size="0.08 0.035" pos="0 0 0.32" rgba="1 1 1 1"/>

      <geom type="cylinder" size="0.06 0.035" pos="0 0 0.37" rgba="1 0.4 0 1"/>
      <geom type="cylinder" size="0.04 0.035" pos="0 0 0.42" rgba="1 1 1 1"/>
    </body>
    <body name="cone_4" pos="8 0 0">
     <joint type="free"/>
    <inertial pos="0 0 0.21"
              mass="0.3"
              diaginertia="0.0015 0.0015 0.0003"/>
      <geom type="cylinder" size="0.22 0.02" pos="0 0 0.02" rgba="0.1 0.1 0.1 1"/>

      <geom type="cylinder" size="0.18 0.035" pos="0 0 0.07" rgba="1 0.4 0 1"/>
      <geom type="cylinder" size="0.16 0.035" pos="0 0 0.12" rgba="1 1 1 1"/>

      <geom type="cylinder" size="0.14 0.035" pos="0 0 0.17" rgba="1 0.4 0 1"/>
      <geom type="cylinder" size="0.12 0.035" pos="0 0 0.22" rgba="1 1 1 1"/>

      <geom type="cylinder" size="0.10 0.035" pos="0 0 0.27" rgba="1 0.4 0 1"/>
      <geom type="cylinder" size="0.08 0.035" pos="0 0 0.32" rgba="1 1 1 1"/>

      <geom type="cylinder" size="0.06 0.035" pos="0 0 0.37" rgba="1 0.4 0 1"/>
      <geom type="cylinder" size="0.04 0.035" pos="0 0 0.42" rgba="1 1 1 1"/>

    </body>


  </worldbody>

  <actuator>
    <motor ctrlrange="-25 25" joint="fl_wheel_joint"/>
    <motor ctrlrange="-25 25" joint="fr_wheel_joint"/>
    <motor ctrlrange="-25 25" joint="bl_wheel_joint"/>
    <motor ctrlrange="-25 25" joint="br_wheel_joint"/>

    <motor ctrlrange="-16 16" joint="fl_steering_joint"/>
    <motor ctrlrange="-16 16" joint="fr_steering_joint"/>
    <motor ctrlrange="-16 16" joint="bl_steering_joint"/>
    <motor ctrlrange="-16 16" joint="br_steering_joint"/>
  </actuator>

</mujoco>